[2024-05-01T00:37:11.797+0000] {local_task_job_runner.py:120} INFO - ::group::Pre task execution logs
[2024-05-01T00:37:11.811+0000] {taskinstance.py:2073} INFO - Dependencies all met for dep_context=non-requeueable deps ti=<TaskInstance: batch_analysis_dag.test_query manual__2024-05-01T00:37:10.628674+00:00 [queued]>
[2024-05-01T00:37:11.816+0000] {taskinstance.py:2073} INFO - Dependencies all met for dep_context=requeueable deps ti=<TaskInstance: batch_analysis_dag.test_query manual__2024-05-01T00:37:10.628674+00:00 [queued]>
[2024-05-01T00:37:11.816+0000] {taskinstance.py:2303} INFO - Starting attempt 1 of 1
[2024-05-01T00:37:11.825+0000] {taskinstance.py:2327} INFO - Executing <Task(_PythonDecoratedOperator): test_query> on 2024-05-01 00:37:10.628674+00:00
[2024-05-01T00:37:11.830+0000] {warnings.py:110} WARNING - /home/***/.local/lib/python3.12/site-packages/***/task/task_runner/standard_task_runner.py:61: DeprecationWarning: This process (pid=546) is multi-threaded, use of fork() may lead to deadlocks in the child.
  pid = os.fork()

[2024-05-01T00:37:11.831+0000] {standard_task_runner.py:63} INFO - Started process 548 to run task
[2024-05-01T00:37:11.832+0000] {standard_task_runner.py:90} INFO - Running: ['***', 'tasks', 'run', 'batch_analysis_dag', 'test_query', 'manual__2024-05-01T00:37:10.628674+00:00', '--job-id', '51', '--raw', '--subdir', 'DAGS_FOLDER/ml-dag.py', '--cfg-path', '/tmp/tmpdeym_8au']
[2024-05-01T00:37:11.834+0000] {standard_task_runner.py:91} INFO - Job 51: Subtask test_query
[2024-05-01T00:37:11.866+0000] {task_command.py:426} INFO - Running <TaskInstance: batch_analysis_dag.test_query manual__2024-05-01T00:37:10.628674+00:00 [running]> on host 0a71bd2d4f31
[2024-05-01T00:37:11.926+0000] {taskinstance.py:2644} INFO - Exporting env vars: AIRFLOW_CTX_DAG_OWNER='***' AIRFLOW_CTX_DAG_ID='batch_analysis_dag' AIRFLOW_CTX_TASK_ID='test_query' AIRFLOW_CTX_EXECUTION_DATE='2024-05-01T00:37:10.628674+00:00' AIRFLOW_CTX_TRY_NUMBER='1' AIRFLOW_CTX_DAG_RUN_ID='manual__2024-05-01T00:37:10.628674+00:00'
[2024-05-01T00:37:11.928+0000] {taskinstance.py:430} INFO - ::endgroup::
[2024-05-01T00:37:11.935+0000] {base.py:84} INFO - Using connection ID 'test-mongo-con' for task execution.
[2024-05-01T00:37:11.944+0000] {taskinstance.py:441} INFO - ::group::Post task execution logs
[2024-05-01T00:37:11.944+0000] {taskinstance.py:2890} ERROR - Task failed with exception
Traceback (most recent call last):
  File "/home/airflow/.local/lib/python3.12/site-packages/airflow/models/taskinstance.py", line 465, in _execute_task
    result = _execute_callable(context=context, **execute_callable_kwargs)
             ^^^^^^^^^^^^^^^^^^^^^^^^^^^^^^^^^^^^^^^^^^^^^^^^^^^^^^^^^^^^^
  File "/home/airflow/.local/lib/python3.12/site-packages/airflow/models/taskinstance.py", line 432, in _execute_callable
    return execute_callable(context=context, **execute_callable_kwargs)
           ^^^^^^^^^^^^^^^^^^^^^^^^^^^^^^^^^^^^^^^^^^^^^^^^^^^^^^^^^^^^
  File "/home/airflow/.local/lib/python3.12/site-packages/airflow/models/baseoperator.py", line 400, in wrapper
    return func(self, *args, **kwargs)
           ^^^^^^^^^^^^^^^^^^^^^^^^^^^
  File "/home/airflow/.local/lib/python3.12/site-packages/airflow/decorators/base.py", line 265, in execute
    return_value = super().execute(context)
                   ^^^^^^^^^^^^^^^^^^^^^^^^
  File "/home/airflow/.local/lib/python3.12/site-packages/airflow/models/baseoperator.py", line 400, in wrapper
    return func(self, *args, **kwargs)
           ^^^^^^^^^^^^^^^^^^^^^^^^^^^
  File "/home/airflow/.local/lib/python3.12/site-packages/airflow/operators/python.py", line 235, in execute
    return_value = self.execute_callable()
                   ^^^^^^^^^^^^^^^^^^^^^^^
  File "/home/airflow/.local/lib/python3.12/site-packages/airflow/operators/python.py", line 252, in execute_callable
    return self.python_callable(*self.op_args, **self.op_kwargs)
           ^^^^^^^^^^^^^^^^^^^^^^^^^^^^^^^^^^^^^^^^^^^^^^^^^^^^^
  File "/opt/airflow/dags/ml-dag.py", line 19, in test_query
    result = connection.find(
             ^^^^^^^^^^^^^^^^
TypeError: 'Database' object is not callable
[2024-05-01T00:37:11.953+0000] {taskinstance.py:1205} INFO - Marking task as FAILED. dag_id=batch_analysis_dag, task_id=test_query, execution_date=20240501T003710, start_date=20240501T003711, end_date=20240501T003711
[2024-05-01T00:37:11.961+0000] {standard_task_runner.py:110} ERROR - Failed to execute job 51 for task test_query ('Database' object is not callable; 548)
[2024-05-01T00:37:12.005+0000] {local_task_job_runner.py:240} INFO - Task exited with return code 1
[2024-05-01T00:37:12.019+0000] {taskinstance.py:3482} INFO - 0 downstream tasks scheduled from follow-on schedule check
[2024-05-01T00:37:12.020+0000] {local_task_job_runner.py:222} INFO - ::endgroup::
