[2024-05-01T00:28:15.601+0000] {local_task_job_runner.py:120} INFO - ::group::Pre task execution logs
[2024-05-01T00:28:15.621+0000] {taskinstance.py:2073} INFO - Dependencies all met for dep_context=non-requeueable deps ti=<TaskInstance: batch_analysis_dag.connect_with_mongo manual__2024-05-01T00:28:11.774835+00:00 [queued]>
[2024-05-01T00:28:15.627+0000] {taskinstance.py:2073} INFO - Dependencies all met for dep_context=requeueable deps ti=<TaskInstance: batch_analysis_dag.connect_with_mongo manual__2024-05-01T00:28:11.774835+00:00 [queued]>
[2024-05-01T00:28:15.627+0000] {taskinstance.py:2303} INFO - Starting attempt 1 of 1
[2024-05-01T00:28:15.638+0000] {taskinstance.py:2327} INFO - Executing <Task(_PythonDecoratedOperator): connect_with_mongo> on 2024-05-01 00:28:11.774835+00:00
[2024-05-01T00:28:15.647+0000] {warnings.py:110} WARNING - /home/***/.local/lib/python3.12/site-packages/***/task/task_runner/standard_task_runner.py:61: DeprecationWarning: This process (pid=415) is multi-threaded, use of fork() may lead to deadlocks in the child.
  pid = os.fork()

[2024-05-01T00:28:15.649+0000] {standard_task_runner.py:63} INFO - Started process 420 to run task
[2024-05-01T00:28:15.648+0000] {standard_task_runner.py:90} INFO - Running: ['***', 'tasks', 'run', 'batch_analysis_dag', 'connect_with_mongo', 'manual__2024-05-01T00:28:11.774835+00:00', '--job-id', '48', '--raw', '--subdir', 'DAGS_FOLDER/ml-dag.py', '--cfg-path', '/tmp/tmps_0h2j1g']
[2024-05-01T00:28:15.651+0000] {standard_task_runner.py:91} INFO - Job 48: Subtask connect_with_mongo
[2024-05-01T00:28:15.704+0000] {task_command.py:426} INFO - Running <TaskInstance: batch_analysis_dag.connect_with_mongo manual__2024-05-01T00:28:11.774835+00:00 [running]> on host 0a71bd2d4f31
[2024-05-01T00:28:15.787+0000] {taskinstance.py:2644} INFO - Exporting env vars: AIRFLOW_CTX_DAG_OWNER='***' AIRFLOW_CTX_DAG_ID='batch_analysis_dag' AIRFLOW_CTX_TASK_ID='connect_with_mongo' AIRFLOW_CTX_EXECUTION_DATE='2024-05-01T00:28:11.774835+00:00' AIRFLOW_CTX_TRY_NUMBER='1' AIRFLOW_CTX_DAG_RUN_ID='manual__2024-05-01T00:28:11.774835+00:00'
[2024-05-01T00:28:15.789+0000] {taskinstance.py:430} INFO - ::endgroup::
[2024-05-01T00:28:15.795+0000] {taskinstance.py:441} INFO - ::group::Post task execution logs
[2024-05-01T00:28:15.805+0000] {taskinstance.py:2890} ERROR - Task failed with exception
Traceback (most recent call last):
  File "/home/airflow/.local/lib/python3.12/site-packages/airflow/models/taskinstance.py", line 465, in _execute_task
    result = _execute_callable(context=context, **execute_callable_kwargs)
             ^^^^^^^^^^^^^^^^^^^^^^^^^^^^^^^^^^^^^^^^^^^^^^^^^^^^^^^^^^^^^
  File "/home/airflow/.local/lib/python3.12/site-packages/airflow/models/taskinstance.py", line 432, in _execute_callable
    return execute_callable(context=context, **execute_callable_kwargs)
           ^^^^^^^^^^^^^^^^^^^^^^^^^^^^^^^^^^^^^^^^^^^^^^^^^^^^^^^^^^^^
  File "/home/airflow/.local/lib/python3.12/site-packages/airflow/models/baseoperator.py", line 400, in wrapper
    return func(self, *args, **kwargs)
           ^^^^^^^^^^^^^^^^^^^^^^^^^^^
  File "/home/airflow/.local/lib/python3.12/site-packages/airflow/decorators/base.py", line 265, in execute
    return_value = super().execute(context)
                   ^^^^^^^^^^^^^^^^^^^^^^^^
  File "/home/airflow/.local/lib/python3.12/site-packages/airflow/models/baseoperator.py", line 400, in wrapper
    return func(self, *args, **kwargs)
           ^^^^^^^^^^^^^^^^^^^^^^^^^^^
  File "/home/airflow/.local/lib/python3.12/site-packages/airflow/operators/python.py", line 235, in execute
    return_value = self.execute_callable()
                   ^^^^^^^^^^^^^^^^^^^^^^^
  File "/home/airflow/.local/lib/python3.12/site-packages/airflow/operators/python.py", line 252, in execute_callable
    return self.python_callable(*self.op_args, **self.op_kwargs)
           ^^^^^^^^^^^^^^^^^^^^^^^^^^^^^^^^^^^^^^^^^^^^^^^^^^^^^
  File "/opt/airflow/dags/ml-dag.py", line 16, in connect_with_mongo
    hook = MongoHook(conn_id="mongo_default")
           ^^^^^^^^^^^^^^^^^^^^^^^^^^^^^^^^^^
  File "/home/airflow/.local/lib/python3.12/site-packages/airflow/providers/mongo/hooks/mongo.py", line 94, in __init__
    self.connection = self.get_connection(self.mongo_conn_id)
                      ^^^^^^^^^^^^^^^^^^^^^^^^^^^^^^^^^^^^^^^
  File "/home/airflow/.local/lib/python3.12/site-packages/airflow/hooks/base.py", line 83, in get_connection
    conn = Connection.get_connection_from_secrets(conn_id)
           ^^^^^^^^^^^^^^^^^^^^^^^^^^^^^^^^^^^^^^^^^^^^^^^
  File "/home/airflow/.local/lib/python3.12/site-packages/airflow/models/connection.py", line 519, in get_connection_from_secrets
    raise AirflowNotFoundException(f"The conn_id `{conn_id}` isn't defined")
airflow.exceptions.AirflowNotFoundException: The conn_id `mongo_default` isn't defined
[2024-05-01T00:28:15.816+0000] {taskinstance.py:1205} INFO - Marking task as FAILED. dag_id=batch_analysis_dag, task_id=connect_with_mongo, execution_date=20240501T002811, start_date=20240501T002815, end_date=20240501T002815
[2024-05-01T00:28:15.827+0000] {standard_task_runner.py:110} ERROR - Failed to execute job 48 for task connect_with_mongo (The conn_id `mongo_default` isn't defined; 420)
[2024-05-01T00:28:15.864+0000] {local_task_job_runner.py:240} INFO - Task exited with return code 1
[2024-05-01T00:28:15.881+0000] {taskinstance.py:3482} INFO - 0 downstream tasks scheduled from follow-on schedule check
[2024-05-01T00:28:15.884+0000] {local_task_job_runner.py:222} INFO - ::endgroup::
