[2024-04-28T02:18:58.173+0000] {local_task_job_runner.py:120} INFO - ::group::Pre task execution logs
[2024-04-28T02:18:58.191+0000] {taskinstance.py:2073} INFO - Dependencies all met for dep_context=non-requeueable deps ti=<TaskInstance: stream-dag.get-object manual__2024-04-28T02:18:56.651007+00:00 [queued]>
[2024-04-28T02:18:58.197+0000] {taskinstance.py:2073} INFO - Dependencies all met for dep_context=requeueable deps ti=<TaskInstance: stream-dag.get-object manual__2024-04-28T02:18:56.651007+00:00 [queued]>
[2024-04-28T02:18:58.198+0000] {taskinstance.py:2303} INFO - Starting attempt 1 of 1
[2024-04-28T02:18:58.209+0000] {taskinstance.py:2327} INFO - Executing <Task(PythonOperator): get-object> on 2024-04-28 02:18:56.651007+00:00
[2024-04-28T02:18:58.216+0000] {warnings.py:110} WARNING - /home/***/.local/lib/python3.12/site-packages/***/task/task_runner/standard_task_runner.py:61: DeprecationWarning: This process (pid=6382) is multi-threaded, use of fork() may lead to deadlocks in the child.
  pid = os.fork()

[2024-04-28T02:18:58.217+0000] {standard_task_runner.py:63} INFO - Started process 6384 to run task
[2024-04-28T02:18:58.217+0000] {standard_task_runner.py:90} INFO - Running: ['***', 'tasks', 'run', 'stream-dag', 'get-object', 'manual__2024-04-28T02:18:56.651007+00:00', '--job-id', '24', '--raw', '--subdir', 'DAGS_FOLDER/new-dag.py', '--cfg-path', '/tmp/tmpe3q0e62e']
[2024-04-28T02:18:58.218+0000] {standard_task_runner.py:91} INFO - Job 24: Subtask get-object
[2024-04-28T02:18:58.248+0000] {task_command.py:426} INFO - Running <TaskInstance: stream-dag.get-object manual__2024-04-28T02:18:56.651007+00:00 [running]> on host 2589f30e9678
[2024-04-28T02:18:58.309+0000] {taskinstance.py:2644} INFO - Exporting env vars: AIRFLOW_CTX_DAG_OWNER='***' AIRFLOW_CTX_DAG_ID='stream-dag' AIRFLOW_CTX_TASK_ID='get-object' AIRFLOW_CTX_EXECUTION_DATE='2024-04-28T02:18:56.651007+00:00' AIRFLOW_CTX_TRY_NUMBER='1' AIRFLOW_CTX_DAG_RUN_ID='manual__2024-04-28T02:18:56.651007+00:00'
[2024-04-28T02:18:58.310+0000] {taskinstance.py:430} INFO - ::endgroup::
[2024-04-28T02:18:59.032+0000] {logging_mixin.py:188} INFO -                      order_id  ...             order_timestamp
0  2024-04-26T01:37:35.566158  ...  2024-04-26T01:37:35.566158

[1 rows x 4 columns]
[2024-04-28T02:18:59.034+0000] {logging_mixin.py:188} INFO -                 order_list_id product_id quantity
0  2024-04-26T01:37:35.566158          1        2
1  2024-04-26T01:37:35.566158          2        3
[2024-04-28T02:18:59.185+0000] {logging_mixin.py:188} INFO -                      order_id  ...             order_timestamp
0  2024-04-26T01:38:54.876610  ...  2024-04-26T01:38:54.876610

[1 rows x 4 columns]
[2024-04-28T02:18:59.187+0000] {logging_mixin.py:188} INFO -                 order_list_id product_id quantity
0  2024-04-26T01:38:54.876610          1        2
1  2024-04-26T01:38:54.876610          2        3
[2024-04-28T02:18:59.332+0000] {logging_mixin.py:188} INFO -                      order_id  ...             order_timestamp
0  2024-04-26T01:51:58.960438  ...  2024-04-26T01:51:58.960438

[1 rows x 4 columns]
[2024-04-28T02:18:59.335+0000] {logging_mixin.py:188} INFO -                 order_list_id product_id quantity
0  2024-04-26T01:51:58.960438          1        2
1  2024-04-26T01:51:58.960438          2        3
[2024-04-28T02:18:59.480+0000] {logging_mixin.py:188} INFO -                      order_id  ...             order_timestamp
0  2024-04-26T00:34:50.821265  ...  2024-04-26T00:34:50.821265

[1 rows x 4 columns]
[2024-04-28T02:18:59.482+0000] {logging_mixin.py:188} INFO -                 order_list_id product_id quantity
0  2024-04-26T00:34:50.821265          1        2
1  2024-04-26T00:34:50.821265          2        3
[2024-04-28T02:19:18.309+0000] {taskinstance.py:441} INFO - ::group::Post task execution logs
[2024-04-28T02:19:18.310+0000] {taskinstance.py:2890} ERROR - Task failed with exception
Traceback (most recent call last):
  File "/home/airflow/.local/lib/python3.12/site-packages/airflow/models/taskinstance.py", line 465, in _execute_task
    result = _execute_callable(context=context, **execute_callable_kwargs)
             ^^^^^^^^^^^^^^^^^^^^^^^^^^^^^^^^^^^^^^^^^^^^^^^^^^^^^^^^^^^^^
  File "/home/airflow/.local/lib/python3.12/site-packages/airflow/models/taskinstance.py", line 432, in _execute_callable
    return execute_callable(context=context, **execute_callable_kwargs)
           ^^^^^^^^^^^^^^^^^^^^^^^^^^^^^^^^^^^^^^^^^^^^^^^^^^^^^^^^^^^^
  File "/home/airflow/.local/lib/python3.12/site-packages/airflow/models/baseoperator.py", line 400, in wrapper
    return func(self, *args, **kwargs)
           ^^^^^^^^^^^^^^^^^^^^^^^^^^^
  File "/home/airflow/.local/lib/python3.12/site-packages/airflow/operators/python.py", line 235, in execute
    return_value = self.execute_callable()
                   ^^^^^^^^^^^^^^^^^^^^^^^
  File "/home/airflow/.local/lib/python3.12/site-packages/airflow/operators/python.py", line 252, in execute_callable
    return self.python_callable(*self.op_args, **self.op_kwargs)
           ^^^^^^^^^^^^^^^^^^^^^^^^^^^^^^^^^^^^^^^^^^^^^^^^^^^^^
  File "/opt/airflow/dags/new-dag.py", line 39, in get_object_task
    data = json.loads(obj_data.decode("utf-8"))
                      ^^^^^^^^^^^^^^^^^^^^^^^^
UnicodeDecodeError: 'utf-8' codec can't decode byte 0xe0 in position 10: invalid continuation byte
[2024-04-28T02:19:18.317+0000] {taskinstance.py:1205} INFO - Marking task as FAILED. dag_id=stream-dag, task_id=get-object, execution_date=20240428T021856, start_date=20240428T021858, end_date=20240428T021918
[2024-04-28T02:19:18.325+0000] {standard_task_runner.py:110} ERROR - Failed to execute job 24 for task get-object ('utf-8' codec can't decode byte 0xe0 in position 10: invalid continuation byte; 6384)
[2024-04-28T02:19:18.336+0000] {local_task_job_runner.py:240} INFO - Task exited with return code 1
[2024-04-28T02:19:18.346+0000] {taskinstance.py:3482} INFO - 0 downstream tasks scheduled from follow-on schedule check
[2024-04-28T02:19:18.347+0000] {local_task_job_runner.py:222} INFO - ::endgroup::
