[2024-04-26T06:45:07.019+0000] {local_task_job_runner.py:120} INFO - ::group::Pre task execution logs
[2024-04-26T06:45:07.037+0000] {taskinstance.py:2073} INFO - Dependencies all met for dep_context=non-requeueable deps ti=<TaskInstance: stream-dag.s3-bucket manual__2024-04-26T06:45:04.786209+00:00 [queued]>
[2024-04-26T06:45:07.042+0000] {taskinstance.py:2073} INFO - Dependencies all met for dep_context=requeueable deps ti=<TaskInstance: stream-dag.s3-bucket manual__2024-04-26T06:45:04.786209+00:00 [queued]>
[2024-04-26T06:45:07.042+0000] {taskinstance.py:2303} INFO - Starting attempt 1 of 1
[2024-04-26T06:45:07.051+0000] {taskinstance.py:2327} INFO - Executing <Task(PythonOperator): s3-bucket> on 2024-04-26 06:45:04.786209+00:00
[2024-04-26T06:45:07.059+0000] {warnings.py:110} WARNING - /home/***/.local/lib/python3.12/site-packages/***/task/task_runner/standard_task_runner.py:61: DeprecationWarning: This process (pid=249) is multi-threaded, use of fork() may lead to deadlocks in the child.
  pid = os.fork()

[2024-04-26T06:45:07.060+0000] {standard_task_runner.py:63} INFO - Started process 251 to run task
[2024-04-26T06:45:07.060+0000] {standard_task_runner.py:90} INFO - Running: ['***', 'tasks', 'run', 'stream-dag', 's3-bucket', 'manual__2024-04-26T06:45:04.786209+00:00', '--job-id', '4', '--raw', '--subdir', 'DAGS_FOLDER/new-dag.py', '--cfg-path', '/tmp/tmplkrbjiq6']
[2024-04-26T06:45:07.062+0000] {standard_task_runner.py:91} INFO - Job 4: Subtask s3-bucket
[2024-04-26T06:45:07.096+0000] {task_command.py:426} INFO - Running <TaskInstance: stream-dag.s3-bucket manual__2024-04-26T06:45:04.786209+00:00 [running]> on host 701d3b82b873
[2024-04-26T06:45:07.166+0000] {taskinstance.py:2644} INFO - Exporting env vars: AIRFLOW_CTX_DAG_OWNER='***' AIRFLOW_CTX_DAG_ID='stream-dag' AIRFLOW_CTX_TASK_ID='s3-bucket' AIRFLOW_CTX_EXECUTION_DATE='2024-04-26T06:45:04.786209+00:00' AIRFLOW_CTX_TRY_NUMBER='1' AIRFLOW_CTX_DAG_RUN_ID='manual__2024-04-26T06:45:04.786209+00:00'
[2024-04-26T06:45:07.168+0000] {taskinstance.py:430} INFO - ::endgroup::
[2024-04-26T06:45:07.972+0000] {taskinstance.py:441} INFO - ::group::Post task execution logs
[2024-04-26T06:45:07.973+0000] {taskinstance.py:2890} ERROR - Task failed with exception
Traceback (most recent call last):
  File "/home/airflow/.local/lib/python3.12/site-packages/airflow/models/taskinstance.py", line 465, in _execute_task
    result = _execute_callable(context=context, **execute_callable_kwargs)
             ^^^^^^^^^^^^^^^^^^^^^^^^^^^^^^^^^^^^^^^^^^^^^^^^^^^^^^^^^^^^^
  File "/home/airflow/.local/lib/python3.12/site-packages/airflow/models/taskinstance.py", line 432, in _execute_callable
    return execute_callable(context=context, **execute_callable_kwargs)
           ^^^^^^^^^^^^^^^^^^^^^^^^^^^^^^^^^^^^^^^^^^^^^^^^^^^^^^^^^^^^
  File "/home/airflow/.local/lib/python3.12/site-packages/airflow/models/baseoperator.py", line 400, in wrapper
    return func(self, *args, **kwargs)
           ^^^^^^^^^^^^^^^^^^^^^^^^^^^
  File "/home/airflow/.local/lib/python3.12/site-packages/airflow/operators/python.py", line 235, in execute
    return_value = self.execute_callable()
                   ^^^^^^^^^^^^^^^^^^^^^^^
  File "/home/airflow/.local/lib/python3.12/site-packages/airflow/operators/python.py", line 252, in execute_callable
    return self.python_callable(*self.op_args, **self.op_kwargs)
           ^^^^^^^^^^^^^^^^^^^^^^^^^^^^^^^^^^^^^^^^^^^^^^^^^^^^^
  File "/opt/airflow/dags/new-dag.py", line 19, in s3Bucket
    response = s3_client.list_buckets()
               ^^^^^^^^^^^^^^^^^^^^^^^^
  File "/home/airflow/.local/lib/python3.12/site-packages/botocore/client.py", line 553, in _api_call
    return self._make_api_call(operation_name, kwargs)
           ^^^^^^^^^^^^^^^^^^^^^^^^^^^^^^^^^^^^^^^^^^^
  File "/home/airflow/.local/lib/python3.12/site-packages/botocore/client.py", line 1009, in _make_api_call
    raise error_class(parsed_response, operation_name)
botocore.exceptions.ClientError: An error occurred (AccessDenied) when calling the ListBuckets operation: Access Denied
[2024-04-26T06:45:07.982+0000] {taskinstance.py:1205} INFO - Marking task as FAILED. dag_id=stream-dag, task_id=s3-bucket, execution_date=20240426T064504, start_date=20240426T064507, end_date=20240426T064507
[2024-04-26T06:45:07.992+0000] {standard_task_runner.py:110} ERROR - Failed to execute job 4 for task s3-bucket (An error occurred (AccessDenied) when calling the ListBuckets operation: Access Denied; 251)
[2024-04-26T06:45:08.036+0000] {local_task_job_runner.py:240} INFO - Task exited with return code 1
[2024-04-26T06:45:08.056+0000] {taskinstance.py:3482} INFO - 0 downstream tasks scheduled from follow-on schedule check
[2024-04-26T06:45:08.057+0000] {local_task_job_runner.py:222} INFO - ::endgroup::
