[2024-04-30T10:38:20.335+0000] {local_task_job_runner.py:120} INFO - ::group::Pre task execution logs
[2024-04-30T10:38:20.365+0000] {taskinstance.py:2073} INFO - Dependencies all met for dep_context=non-requeueable deps ti=<TaskInstance: test-docker-dag.test-docker manual__2024-04-30T10:38:16.913383+00:00 [queued]>
[2024-04-30T10:38:20.385+0000] {taskinstance.py:2073} INFO - Dependencies all met for dep_context=requeueable deps ti=<TaskInstance: test-docker-dag.test-docker manual__2024-04-30T10:38:16.913383+00:00 [queued]>
[2024-04-30T10:38:20.386+0000] {taskinstance.py:2303} INFO - Starting attempt 1 of 1
[2024-04-30T10:38:20.409+0000] {taskinstance.py:2327} INFO - Executing <Task(DockerOperator): test-docker> on 2024-04-30 10:38:16.913383+00:00
[2024-04-30T10:38:20.424+0000] {warnings.py:110} WARNING - /home/***/.local/lib/python3.12/site-packages/***/task/task_runner/standard_task_runner.py:61: DeprecationWarning: This process (pid=872) is multi-threaded, use of fork() may lead to deadlocks in the child.
  pid = os.fork()

[2024-04-30T10:38:20.426+0000] {standard_task_runner.py:63} INFO - Started process 874 to run task
[2024-04-30T10:38:20.426+0000] {standard_task_runner.py:90} INFO - Running: ['***', 'tasks', 'run', 'test-docker-dag', 'test-docker', 'manual__2024-04-30T10:38:16.913383+00:00', '--job-id', '40', '--raw', '--subdir', 'DAGS_FOLDER/ml-dag.py', '--cfg-path', '/tmp/tmp7z_qwtru']
[2024-04-30T10:38:20.431+0000] {standard_task_runner.py:91} INFO - Job 40: Subtask test-docker
[2024-04-30T10:38:20.501+0000] {task_command.py:426} INFO - Running <TaskInstance: test-docker-dag.test-docker manual__2024-04-30T10:38:16.913383+00:00 [running]> on host 16ea965681b4
[2024-04-30T10:38:20.636+0000] {taskinstance.py:2644} INFO - Exporting env vars: AIRFLOW_CTX_DAG_OWNER='***' AIRFLOW_CTX_DAG_ID='test-docker-dag' AIRFLOW_CTX_TASK_ID='test-docker' AIRFLOW_CTX_EXECUTION_DATE='2024-04-30T10:38:16.913383+00:00' AIRFLOW_CTX_TRY_NUMBER='1' AIRFLOW_CTX_DAG_RUN_ID='manual__2024-04-30T10:38:16.913383+00:00'
[2024-04-30T10:38:20.640+0000] {taskinstance.py:430} INFO - ::endgroup::
[2024-04-30T10:38:20.644+0000] {taskinstance.py:441} INFO - ::group::Post task execution logs
[2024-04-30T10:38:20.645+0000] {taskinstance.py:2890} ERROR - Task failed with exception
Traceback (most recent call last):
  File "/home/airflow/.local/lib/python3.12/site-packages/urllib3/connectionpool.py", line 715, in urlopen
    httplib_response = self._make_request(
                       ^^^^^^^^^^^^^^^^^^^
  File "/home/airflow/.local/lib/python3.12/site-packages/urllib3/connectionpool.py", line 416, in _make_request
    conn.request(method, url, **httplib_request_kw)
  File "/home/airflow/.local/lib/python3.12/site-packages/urllib3/connection.py", line 244, in request
    super(HTTPConnection, self).request(method, url, body=body, headers=headers)
  File "/usr/local/lib/python3.12/http/client.py", line 1331, in request
    self._send_request(method, url, body, headers, encode_chunked)
  File "/usr/local/lib/python3.12/http/client.py", line 1377, in _send_request
    self.endheaders(body, encode_chunked=encode_chunked)
  File "/usr/local/lib/python3.12/http/client.py", line 1326, in endheaders
    self._send_output(message_body, encode_chunked=encode_chunked)
  File "/usr/local/lib/python3.12/http/client.py", line 1085, in _send_output
    self.send(msg)
  File "/usr/local/lib/python3.12/http/client.py", line 1029, in send
    self.connect()
  File "/home/airflow/.local/lib/python3.12/site-packages/docker/transport/unixconn.py", line 27, in connect
    sock.connect(self.unix_socket)
FileNotFoundError: [Errno 2] No such file or directory

During handling of the above exception, another exception occurred:

Traceback (most recent call last):
  File "/home/airflow/.local/lib/python3.12/site-packages/requests/adapters.py", line 486, in send
    resp = conn.urlopen(
           ^^^^^^^^^^^^^
  File "/home/airflow/.local/lib/python3.12/site-packages/urllib3/connectionpool.py", line 799, in urlopen
    retries = retries.increment(
              ^^^^^^^^^^^^^^^^^^
  File "/home/airflow/.local/lib/python3.12/site-packages/urllib3/util/retry.py", line 550, in increment
    raise six.reraise(type(error), error, _stacktrace)
          ^^^^^^^^^^^^^^^^^^^^^^^^^^^^^^^^^^^^^^^^^^^^
  File "/home/airflow/.local/lib/python3.12/site-packages/urllib3/packages/six.py", line 769, in reraise
    raise value.with_traceback(tb)
  File "/home/airflow/.local/lib/python3.12/site-packages/urllib3/connectionpool.py", line 715, in urlopen
    httplib_response = self._make_request(
                       ^^^^^^^^^^^^^^^^^^^
  File "/home/airflow/.local/lib/python3.12/site-packages/urllib3/connectionpool.py", line 416, in _make_request
    conn.request(method, url, **httplib_request_kw)
  File "/home/airflow/.local/lib/python3.12/site-packages/urllib3/connection.py", line 244, in request
    super(HTTPConnection, self).request(method, url, body=body, headers=headers)
  File "/usr/local/lib/python3.12/http/client.py", line 1331, in request
    self._send_request(method, url, body, headers, encode_chunked)
  File "/usr/local/lib/python3.12/http/client.py", line 1377, in _send_request
    self.endheaders(body, encode_chunked=encode_chunked)
  File "/usr/local/lib/python3.12/http/client.py", line 1326, in endheaders
    self._send_output(message_body, encode_chunked=encode_chunked)
  File "/usr/local/lib/python3.12/http/client.py", line 1085, in _send_output
    self.send(msg)
  File "/usr/local/lib/python3.12/http/client.py", line 1029, in send
    self.connect()
  File "/home/airflow/.local/lib/python3.12/site-packages/docker/transport/unixconn.py", line 27, in connect
    sock.connect(self.unix_socket)
urllib3.exceptions.ProtocolError: ('Connection aborted.', FileNotFoundError(2, 'No such file or directory'))

During handling of the above exception, another exception occurred:

Traceback (most recent call last):
  File "/home/airflow/.local/lib/python3.12/site-packages/docker/api/client.py", line 213, in _retrieve_server_version
    return self.version(api_version=False)["ApiVersion"]
           ^^^^^^^^^^^^^^^^^^^^^^^^^^^^^^^
  File "/home/airflow/.local/lib/python3.12/site-packages/docker/api/daemon.py", line 181, in version
    return self._result(self._get(url), json=True)
                        ^^^^^^^^^^^^^^
  File "/home/airflow/.local/lib/python3.12/site-packages/docker/utils/decorators.py", line 44, in inner
    return f(self, *args, **kwargs)
           ^^^^^^^^^^^^^^^^^^^^^^^^
  File "/home/airflow/.local/lib/python3.12/site-packages/docker/api/client.py", line 236, in _get
    return self.get(url, **self._set_request_timeout(kwargs))
           ^^^^^^^^^^^^^^^^^^^^^^^^^^^^^^^^^^^^^^^^^^^^^^^^^^
  File "/home/airflow/.local/lib/python3.12/site-packages/requests/sessions.py", line 602, in get
    return self.request("GET", url, **kwargs)
           ^^^^^^^^^^^^^^^^^^^^^^^^^^^^^^^^^^
  File "/home/airflow/.local/lib/python3.12/site-packages/requests/sessions.py", line 589, in request
    resp = self.send(prep, **send_kwargs)
           ^^^^^^^^^^^^^^^^^^^^^^^^^^^^^^
  File "/home/airflow/.local/lib/python3.12/site-packages/requests/sessions.py", line 703, in send
    r = adapter.send(request, **kwargs)
        ^^^^^^^^^^^^^^^^^^^^^^^^^^^^^^^
  File "/home/airflow/.local/lib/python3.12/site-packages/requests/adapters.py", line 501, in send
    raise ConnectionError(err, request=request)
requests.exceptions.ConnectionError: ('Connection aborted.', FileNotFoundError(2, 'No such file or directory'))

The above exception was the direct cause of the following exception:

Traceback (most recent call last):
  File "/home/airflow/.local/lib/python3.12/site-packages/airflow/models/taskinstance.py", line 465, in _execute_task
    result = _execute_callable(context=context, **execute_callable_kwargs)
             ^^^^^^^^^^^^^^^^^^^^^^^^^^^^^^^^^^^^^^^^^^^^^^^^^^^^^^^^^^^^^
  File "/home/airflow/.local/lib/python3.12/site-packages/airflow/models/taskinstance.py", line 432, in _execute_callable
    return execute_callable(context=context, **execute_callable_kwargs)
           ^^^^^^^^^^^^^^^^^^^^^^^^^^^^^^^^^^^^^^^^^^^^^^^^^^^^^^^^^^^^
  File "/home/airflow/.local/lib/python3.12/site-packages/airflow/models/baseoperator.py", line 400, in wrapper
    return func(self, *args, **kwargs)
           ^^^^^^^^^^^^^^^^^^^^^^^^^^^
  File "/home/airflow/.local/lib/python3.12/site-packages/airflow/providers/docker/operators/docker.py", line 485, in execute
    if self.force_pull or not self.cli.images(name=self.image):
                              ^^^^^^^^
  File "/home/airflow/.local/lib/python3.12/site-packages/airflow/providers/docker/operators/docker.py", line 355, in cli
    return self.hook.api_client
           ^^^^^^^^^^^^^^^^^^^^
  File "/usr/local/lib/python3.12/functools.py", line 995, in __get__
    val = self.func(instance)
          ^^^^^^^^^^^^^^^^^^^
  File "/home/airflow/.local/lib/python3.12/site-packages/airflow/providers/docker/hooks/docker.py", line 149, in api_client
    client = APIClient(
             ^^^^^^^^^^
  File "/home/airflow/.local/lib/python3.12/site-packages/docker/api/client.py", line 197, in __init__
    self._version = self._retrieve_server_version()
                    ^^^^^^^^^^^^^^^^^^^^^^^^^^^^^^^
  File "/home/airflow/.local/lib/python3.12/site-packages/docker/api/client.py", line 220, in _retrieve_server_version
    raise DockerException(
docker.errors.DockerException: Error while fetching server API version: ('Connection aborted.', FileNotFoundError(2, 'No such file or directory'))
[2024-04-30T10:38:20.674+0000] {taskinstance.py:1205} INFO - Marking task as FAILED. dag_id=test-docker-dag, task_id=test-docker, execution_date=20240430T103816, start_date=20240430T103820, end_date=20240430T103820
[2024-04-30T10:38:20.690+0000] {standard_task_runner.py:110} ERROR - Failed to execute job 40 for task test-docker (Error while fetching server API version: ('Connection aborted.', FileNotFoundError(2, 'No such file or directory')); 874)
[2024-04-30T10:38:20.721+0000] {local_task_job_runner.py:240} INFO - Task exited with return code 1
[2024-04-30T10:38:20.745+0000] {taskinstance.py:3482} INFO - 0 downstream tasks scheduled from follow-on schedule check
[2024-04-30T10:38:20.747+0000] {local_task_job_runner.py:222} INFO - ::endgroup::
